<?xml version="1.0" encoding="UTF-8"?>
<testng-results ignored="4" total="10" passed="0" failed="1" skipped="5">
  <reporter-output>
  </reporter-output>
  <suite started-at="2024-05-05T18:56:52Z" name="Default suite" finished-at="2024-05-05T18:57:26Z" duration-ms="34212">
    <groups>
    </groups>
    <test started-at="2024-05-05T18:56:52Z" name="Default test" finished-at="2024-05-05T18:57:26Z" duration-ms="34212">
      <class name="com.automation.Day16_5th_May_2024_TestNG_retry_failed_TestCases.First_Way_LoginTest_retry_failed">
        <test-method is-config="true" signature="setup()[pri:0, instance:com.automation.Day16_5th_May_2024_TestNG_retry_failed_TestCases.First_Way_LoginTest_retry_failed@740fb309]" started-at="2024-05-05T14:56:52Z" name="setup" finished-at="2024-05-05T14:56:58Z" duration-ms="5300" status="PASS">
          <reporter-output>
          </reporter-output>
        </test-method> <!-- setup -->
        <test-method signature="noCredentials()[pri:5, instance:com.automation.Day16_5th_May_2024_TestNG_retry_failed_TestCases.First_Way_LoginTest_retry_failed@740fb309]" started-at="2024-05-05T14:56:58Z" name="noCredentials" finished-at="2024-05-05T14:56:58Z" duration-ms="560" status="SKIP">
          <exception class="java.lang.AssertionError">
            <message>
              <![CDATA[expected [false] but found [true]]]>
            </message>
            <full-stacktrace>
              <![CDATA[java.lang.AssertionError: expected [false] but found [true]
	at org.testng.Assert.fail(Assert.java:93)
	at org.testng.Assert.failNotEquals(Assert.java:512)
	at org.testng.Assert.assertFalse(Assert.java:62)
	at org.testng.Assert.assertFalse(Assert.java:72)
	at com.automation.Day16_5th_May_2024_TestNG_retry_failed_TestCases.First_Way_LoginTest_retry_failed.noCredentials(First_Way_LoginTest_retry_failed.java:72)
	at java.base/jdk.internal.reflect.NativeMethodAccessorImpl.invoke0(Native Method)
	at java.base/jdk.internal.reflect.NativeMethodAccessorImpl.invoke(NativeMethodAccessorImpl.java:77)
	at java.base/jdk.internal.reflect.DelegatingMethodAccessorImpl.invoke(DelegatingMethodAccessorImpl.java:43)
	at java.base/java.lang.reflect.Method.invoke(Method.java:568)
	at org.testng.internal.MethodInvocationHelper.invokeMethod(MethodInvocationHelper.java:108)
	at org.testng.internal.Invoker.invokeMethod(Invoker.java:661)
	at org.testng.internal.Invoker.invokeTestMethod(Invoker.java:869)
	at org.testng.internal.Invoker.invokeTestMethods(Invoker.java:1193)
	at org.testng.internal.TestMethodWorker.invokeTestMethods(TestMethodWorker.java:126)
	at org.testng.internal.TestMethodWorker.run(TestMethodWorker.java:109)
	at org.testng.TestRunner.privateRun(TestRunner.java:744)
	at org.testng.TestRunner.run(TestRunner.java:602)
	at org.testng.SuiteRunner.runTest(SuiteRunner.java:380)
	at org.testng.SuiteRunner.runSequentially(SuiteRunner.java:375)
	at org.testng.SuiteRunner.privateRun(SuiteRunner.java:340)
	at org.testng.SuiteRunner.run(SuiteRunner.java:289)
	at org.testng.SuiteRunnerWorker.runSuite(SuiteRunnerWorker.java:52)
	at org.testng.SuiteRunnerWorker.run(SuiteRunnerWorker.java:86)
	at org.testng.TestNG.runSuitesSequentially(TestNG.java:1301)
	at org.testng.TestNG.runSuitesLocally(TestNG.java:1226)
	at org.testng.TestNG.runSuites(TestNG.java:1144)
	at org.testng.TestNG.run(TestNG.java:1115)
	at org.testng.remote.AbstractRemoteTestNG.run(AbstractRemoteTestNG.java:115)
	at org.testng.remote.RemoteTestNG.initAndRun(RemoteTestNG.java:251)
	at org.testng.remote.RemoteTestNG.main(RemoteTestNG.java:77)
]]>
            </full-stacktrace>
          </exception> <!-- java.lang.AssertionError -->
          <reporter-output>
          </reporter-output>
        </test-method> <!-- noCredentials -->
        <test-method is-config="true" signature="tearDown()[pri:0, instance:com.automation.Day16_5th_May_2024_TestNG_retry_failed_TestCases.First_Way_LoginTest_retry_failed@740fb309]" started-at="2024-05-05T14:56:58Z" name="tearDown" finished-at="2024-05-05T14:56:58Z" duration-ms="331" status="PASS">
          <reporter-output>
          </reporter-output>
        </test-method> <!-- tearDown -->
        <test-method is-config="true" signature="setup()[pri:0, instance:com.automation.Day16_5th_May_2024_TestNG_retry_failed_TestCases.First_Way_LoginTest_retry_failed@740fb309]" started-at="2024-05-05T14:56:58Z" name="setup" finished-at="2024-05-05T14:57:03Z" duration-ms="4798" status="PASS">
          <reporter-output>
          </reporter-output>
        </test-method> <!-- setup -->
        <test-method signature="noCredentials()[pri:5, instance:com.automation.Day16_5th_May_2024_TestNG_retry_failed_TestCases.First_Way_LoginTest_retry_failed@740fb309]" started-at="2024-05-05T14:57:03Z" name="noCredentials" finished-at="2024-05-05T14:57:04Z" duration-ms="614" status="SKIP">
          <exception class="java.lang.AssertionError">
            <message>
              <![CDATA[expected [false] but found [true]]]>
            </message>
            <full-stacktrace>
              <![CDATA[java.lang.AssertionError: expected [false] but found [true]
	at org.testng.Assert.fail(Assert.java:93)
	at org.testng.Assert.failNotEquals(Assert.java:512)
	at org.testng.Assert.assertFalse(Assert.java:62)
	at org.testng.Assert.assertFalse(Assert.java:72)
	at com.automation.Day16_5th_May_2024_TestNG_retry_failed_TestCases.First_Way_LoginTest_retry_failed.noCredentials(First_Way_LoginTest_retry_failed.java:72)
	at java.base/jdk.internal.reflect.NativeMethodAccessorImpl.invoke0(Native Method)
	at java.base/jdk.internal.reflect.NativeMethodAccessorImpl.invoke(NativeMethodAccessorImpl.java:77)
	at java.base/jdk.internal.reflect.DelegatingMethodAccessorImpl.invoke(DelegatingMethodAccessorImpl.java:43)
	at java.base/java.lang.reflect.Method.invoke(Method.java:568)
	at org.testng.internal.MethodInvocationHelper.invokeMethod(MethodInvocationHelper.java:108)
	at org.testng.internal.Invoker.invokeMethod(Invoker.java:661)
	at org.testng.internal.Invoker.retryFailed(Invoker.java:1014)
	at org.testng.internal.Invoker.invokeTestMethods(Invoker.java:1215)
	at org.testng.internal.TestMethodWorker.invokeTestMethods(TestMethodWorker.java:126)
	at org.testng.internal.TestMethodWorker.run(TestMethodWorker.java:109)
	at org.testng.TestRunner.privateRun(TestRunner.java:744)
	at org.testng.TestRunner.run(TestRunner.java:602)
	at org.testng.SuiteRunner.runTest(SuiteRunner.java:380)
	at org.testng.SuiteRunner.runSequentially(SuiteRunner.java:375)
	at org.testng.SuiteRunner.privateRun(SuiteRunner.java:340)
	at org.testng.SuiteRunner.run(SuiteRunner.java:289)
	at org.testng.SuiteRunnerWorker.runSuite(SuiteRunnerWorker.java:52)
	at org.testng.SuiteRunnerWorker.run(SuiteRunnerWorker.java:86)
	at org.testng.TestNG.runSuitesSequentially(TestNG.java:1301)
	at org.testng.TestNG.runSuitesLocally(TestNG.java:1226)
	at org.testng.TestNG.runSuites(TestNG.java:1144)
	at org.testng.TestNG.run(TestNG.java:1115)
	at org.testng.remote.AbstractRemoteTestNG.run(AbstractRemoteTestNG.java:115)
	at org.testng.remote.RemoteTestNG.initAndRun(RemoteTestNG.java:251)
	at org.testng.remote.RemoteTestNG.main(RemoteTestNG.java:77)
]]>
            </full-stacktrace>
          </exception> <!-- java.lang.AssertionError -->
          <reporter-output>
          </reporter-output>
        </test-method> <!-- noCredentials -->
        <test-method is-config="true" signature="tearDown()[pri:0, instance:com.automation.Day16_5th_May_2024_TestNG_retry_failed_TestCases.First_Way_LoginTest_retry_failed@740fb309]" started-at="2024-05-05T14:57:04Z" name="tearDown" finished-at="2024-05-05T14:57:04Z" duration-ms="316" status="PASS">
          <reporter-output>
          </reporter-output>
        </test-method> <!-- tearDown -->
        <test-method is-config="true" signature="setup()[pri:0, instance:com.automation.Day16_5th_May_2024_TestNG_retry_failed_TestCases.First_Way_LoginTest_retry_failed@740fb309]" started-at="2024-05-05T14:57:04Z" name="setup" finished-at="2024-05-05T14:57:09Z" duration-ms="4768" status="PASS">
          <reporter-output>
          </reporter-output>
        </test-method> <!-- setup -->
        <test-method signature="noCredentials()[pri:5, instance:com.automation.Day16_5th_May_2024_TestNG_retry_failed_TestCases.First_Way_LoginTest_retry_failed@740fb309]" started-at="2024-05-05T14:57:09Z" name="noCredentials" finished-at="2024-05-05T14:57:10Z" duration-ms="620" status="SKIP">
          <exception class="java.lang.AssertionError">
            <message>
              <![CDATA[expected [false] but found [true]]]>
            </message>
            <full-stacktrace>
              <![CDATA[java.lang.AssertionError: expected [false] but found [true]
	at org.testng.Assert.fail(Assert.java:93)
	at org.testng.Assert.failNotEquals(Assert.java:512)
	at org.testng.Assert.assertFalse(Assert.java:62)
	at org.testng.Assert.assertFalse(Assert.java:72)
	at com.automation.Day16_5th_May_2024_TestNG_retry_failed_TestCases.First_Way_LoginTest_retry_failed.noCredentials(First_Way_LoginTest_retry_failed.java:72)
	at java.base/jdk.internal.reflect.NativeMethodAccessorImpl.invoke0(Native Method)
	at java.base/jdk.internal.reflect.NativeMethodAccessorImpl.invoke(NativeMethodAccessorImpl.java:77)
	at java.base/jdk.internal.reflect.DelegatingMethodAccessorImpl.invoke(DelegatingMethodAccessorImpl.java:43)
	at java.base/java.lang.reflect.Method.invoke(Method.java:568)
	at org.testng.internal.MethodInvocationHelper.invokeMethod(MethodInvocationHelper.java:108)
	at org.testng.internal.Invoker.invokeMethod(Invoker.java:661)
	at org.testng.internal.Invoker.retryFailed(Invoker.java:1014)
	at org.testng.internal.Invoker.invokeTestMethods(Invoker.java:1215)
	at org.testng.internal.TestMethodWorker.invokeTestMethods(TestMethodWorker.java:126)
	at org.testng.internal.TestMethodWorker.run(TestMethodWorker.java:109)
	at org.testng.TestRunner.privateRun(TestRunner.java:744)
	at org.testng.TestRunner.run(TestRunner.java:602)
	at org.testng.SuiteRunner.runTest(SuiteRunner.java:380)
	at org.testng.SuiteRunner.runSequentially(SuiteRunner.java:375)
	at org.testng.SuiteRunner.privateRun(SuiteRunner.java:340)
	at org.testng.SuiteRunner.run(SuiteRunner.java:289)
	at org.testng.SuiteRunnerWorker.runSuite(SuiteRunnerWorker.java:52)
	at org.testng.SuiteRunnerWorker.run(SuiteRunnerWorker.java:86)
	at org.testng.TestNG.runSuitesSequentially(TestNG.java:1301)
	at org.testng.TestNG.runSuitesLocally(TestNG.java:1226)
	at org.testng.TestNG.runSuites(TestNG.java:1144)
	at org.testng.TestNG.run(TestNG.java:1115)
	at org.testng.remote.AbstractRemoteTestNG.run(AbstractRemoteTestNG.java:115)
	at org.testng.remote.RemoteTestNG.initAndRun(RemoteTestNG.java:251)
	at org.testng.remote.RemoteTestNG.main(RemoteTestNG.java:77)
]]>
            </full-stacktrace>
          </exception> <!-- java.lang.AssertionError -->
          <reporter-output>
          </reporter-output>
        </test-method> <!-- noCredentials -->
        <test-method is-config="true" signature="tearDown()[pri:0, instance:com.automation.Day16_5th_May_2024_TestNG_retry_failed_TestCases.First_Way_LoginTest_retry_failed@740fb309]" started-at="2024-05-05T14:57:10Z" name="tearDown" finished-at="2024-05-05T14:57:10Z" duration-ms="305" status="PASS">
          <reporter-output>
          </reporter-output>
        </test-method> <!-- tearDown -->
        <test-method is-config="true" signature="setup()[pri:0, instance:com.automation.Day16_5th_May_2024_TestNG_retry_failed_TestCases.First_Way_LoginTest_retry_failed@740fb309]" started-at="2024-05-05T14:57:10Z" name="setup" finished-at="2024-05-05T14:57:15Z" duration-ms="4729" status="PASS">
          <reporter-output>
          </reporter-output>
        </test-method> <!-- setup -->
        <test-method signature="noCredentials()[pri:5, instance:com.automation.Day16_5th_May_2024_TestNG_retry_failed_TestCases.First_Way_LoginTest_retry_failed@740fb309]" started-at="2024-05-05T14:57:15Z" name="noCredentials" finished-at="2024-05-05T14:57:15Z" duration-ms="539" status="SKIP">
          <exception class="java.lang.AssertionError">
            <message>
              <![CDATA[expected [false] but found [true]]]>
            </message>
            <full-stacktrace>
              <![CDATA[java.lang.AssertionError: expected [false] but found [true]
	at org.testng.Assert.fail(Assert.java:93)
	at org.testng.Assert.failNotEquals(Assert.java:512)
	at org.testng.Assert.assertFalse(Assert.java:62)
	at org.testng.Assert.assertFalse(Assert.java:72)
	at com.automation.Day16_5th_May_2024_TestNG_retry_failed_TestCases.First_Way_LoginTest_retry_failed.noCredentials(First_Way_LoginTest_retry_failed.java:72)
	at java.base/jdk.internal.reflect.NativeMethodAccessorImpl.invoke0(Native Method)
	at java.base/jdk.internal.reflect.NativeMethodAccessorImpl.invoke(NativeMethodAccessorImpl.java:77)
	at java.base/jdk.internal.reflect.DelegatingMethodAccessorImpl.invoke(DelegatingMethodAccessorImpl.java:43)
	at java.base/java.lang.reflect.Method.invoke(Method.java:568)
	at org.testng.internal.MethodInvocationHelper.invokeMethod(MethodInvocationHelper.java:108)
	at org.testng.internal.Invoker.invokeMethod(Invoker.java:661)
	at org.testng.internal.Invoker.retryFailed(Invoker.java:1014)
	at org.testng.internal.Invoker.invokeTestMethods(Invoker.java:1215)
	at org.testng.internal.TestMethodWorker.invokeTestMethods(TestMethodWorker.java:126)
	at org.testng.internal.TestMethodWorker.run(TestMethodWorker.java:109)
	at org.testng.TestRunner.privateRun(TestRunner.java:744)
	at org.testng.TestRunner.run(TestRunner.java:602)
	at org.testng.SuiteRunner.runTest(SuiteRunner.java:380)
	at org.testng.SuiteRunner.runSequentially(SuiteRunner.java:375)
	at org.testng.SuiteRunner.privateRun(SuiteRunner.java:340)
	at org.testng.SuiteRunner.run(SuiteRunner.java:289)
	at org.testng.SuiteRunnerWorker.runSuite(SuiteRunnerWorker.java:52)
	at org.testng.SuiteRunnerWorker.run(SuiteRunnerWorker.java:86)
	at org.testng.TestNG.runSuitesSequentially(TestNG.java:1301)
	at org.testng.TestNG.runSuitesLocally(TestNG.java:1226)
	at org.testng.TestNG.runSuites(TestNG.java:1144)
	at org.testng.TestNG.run(TestNG.java:1115)
	at org.testng.remote.AbstractRemoteTestNG.run(AbstractRemoteTestNG.java:115)
	at org.testng.remote.RemoteTestNG.initAndRun(RemoteTestNG.java:251)
	at org.testng.remote.RemoteTestNG.main(RemoteTestNG.java:77)
]]>
            </full-stacktrace>
          </exception> <!-- java.lang.AssertionError -->
          <reporter-output>
          </reporter-output>
        </test-method> <!-- noCredentials -->
        <test-method is-config="true" signature="tearDown()[pri:0, instance:com.automation.Day16_5th_May_2024_TestNG_retry_failed_TestCases.First_Way_LoginTest_retry_failed@740fb309]" started-at="2024-05-05T14:57:15Z" name="tearDown" finished-at="2024-05-05T14:57:15Z" duration-ms="288" status="PASS">
          <reporter-output>
          </reporter-output>
        </test-method> <!-- tearDown -->
        <test-method is-config="true" signature="setup()[pri:0, instance:com.automation.Day16_5th_May_2024_TestNG_retry_failed_TestCases.First_Way_LoginTest_retry_failed@740fb309]" started-at="2024-05-05T14:57:15Z" name="setup" finished-at="2024-05-05T14:57:20Z" duration-ms="4599" status="PASS">
          <reporter-output>
          </reporter-output>
        </test-method> <!-- setup -->
        <test-method signature="noCredentials()[pri:5, instance:com.automation.Day16_5th_May_2024_TestNG_retry_failed_TestCases.First_Way_LoginTest_retry_failed@740fb309]" started-at="2024-05-05T14:57:20Z" name="noCredentials" finished-at="2024-05-05T14:57:21Z" duration-ms="558" status="SKIP">
          <exception class="java.lang.AssertionError">
            <message>
              <![CDATA[expected [false] but found [true]]]>
            </message>
            <full-stacktrace>
              <![CDATA[java.lang.AssertionError: expected [false] but found [true]
	at org.testng.Assert.fail(Assert.java:93)
	at org.testng.Assert.failNotEquals(Assert.java:512)
	at org.testng.Assert.assertFalse(Assert.java:62)
	at org.testng.Assert.assertFalse(Assert.java:72)
	at com.automation.Day16_5th_May_2024_TestNG_retry_failed_TestCases.First_Way_LoginTest_retry_failed.noCredentials(First_Way_LoginTest_retry_failed.java:72)
	at java.base/jdk.internal.reflect.NativeMethodAccessorImpl.invoke0(Native Method)
	at java.base/jdk.internal.reflect.NativeMethodAccessorImpl.invoke(NativeMethodAccessorImpl.java:77)
	at java.base/jdk.internal.reflect.DelegatingMethodAccessorImpl.invoke(DelegatingMethodAccessorImpl.java:43)
	at java.base/java.lang.reflect.Method.invoke(Method.java:568)
	at org.testng.internal.MethodInvocationHelper.invokeMethod(MethodInvocationHelper.java:108)
	at org.testng.internal.Invoker.invokeMethod(Invoker.java:661)
	at org.testng.internal.Invoker.retryFailed(Invoker.java:1014)
	at org.testng.internal.Invoker.invokeTestMethods(Invoker.java:1215)
	at org.testng.internal.TestMethodWorker.invokeTestMethods(TestMethodWorker.java:126)
	at org.testng.internal.TestMethodWorker.run(TestMethodWorker.java:109)
	at org.testng.TestRunner.privateRun(TestRunner.java:744)
	at org.testng.TestRunner.run(TestRunner.java:602)
	at org.testng.SuiteRunner.runTest(SuiteRunner.java:380)
	at org.testng.SuiteRunner.runSequentially(SuiteRunner.java:375)
	at org.testng.SuiteRunner.privateRun(SuiteRunner.java:340)
	at org.testng.SuiteRunner.run(SuiteRunner.java:289)
	at org.testng.SuiteRunnerWorker.runSuite(SuiteRunnerWorker.java:52)
	at org.testng.SuiteRunnerWorker.run(SuiteRunnerWorker.java:86)
	at org.testng.TestNG.runSuitesSequentially(TestNG.java:1301)
	at org.testng.TestNG.runSuitesLocally(TestNG.java:1226)
	at org.testng.TestNG.runSuites(TestNG.java:1144)
	at org.testng.TestNG.run(TestNG.java:1115)
	at org.testng.remote.AbstractRemoteTestNG.run(AbstractRemoteTestNG.java:115)
	at org.testng.remote.RemoteTestNG.initAndRun(RemoteTestNG.java:251)
	at org.testng.remote.RemoteTestNG.main(RemoteTestNG.java:77)
]]>
            </full-stacktrace>
          </exception> <!-- java.lang.AssertionError -->
          <reporter-output>
          </reporter-output>
        </test-method> <!-- noCredentials -->
        <test-method is-config="true" signature="tearDown()[pri:0, instance:com.automation.Day16_5th_May_2024_TestNG_retry_failed_TestCases.First_Way_LoginTest_retry_failed@740fb309]" started-at="2024-05-05T14:57:21Z" name="tearDown" finished-at="2024-05-05T14:57:21Z" duration-ms="253" status="PASS">
          <reporter-output>
          </reporter-output>
        </test-method> <!-- tearDown -->
        <test-method is-config="true" signature="setup()[pri:0, instance:com.automation.Day16_5th_May_2024_TestNG_retry_failed_TestCases.First_Way_LoginTest_retry_failed@740fb309]" started-at="2024-05-05T14:57:21Z" name="setup" finished-at="2024-05-05T14:57:26Z" duration-ms="4756" status="PASS">
          <reporter-output>
          </reporter-output>
        </test-method> <!-- setup -->
        <test-method signature="noCredentials()[pri:5, instance:com.automation.Day16_5th_May_2024_TestNG_retry_failed_TestCases.First_Way_LoginTest_retry_failed@740fb309]" started-at="2024-05-05T14:57:26Z" name="noCredentials" finished-at="2024-05-05T14:57:26Z" duration-ms="564" status="FAIL">
          <exception class="java.lang.AssertionError">
            <message>
              <![CDATA[expected [false] but found [true]]]>
            </message>
            <full-stacktrace>
              <![CDATA[java.lang.AssertionError: expected [false] but found [true]
	at org.testng.Assert.fail(Assert.java:93)
	at org.testng.Assert.failNotEquals(Assert.java:512)
	at org.testng.Assert.assertFalse(Assert.java:62)
	at org.testng.Assert.assertFalse(Assert.java:72)
	at com.automation.Day16_5th_May_2024_TestNG_retry_failed_TestCases.First_Way_LoginTest_retry_failed.noCredentials(First_Way_LoginTest_retry_failed.java:72)
	at java.base/jdk.internal.reflect.NativeMethodAccessorImpl.invoke0(Native Method)
	at java.base/jdk.internal.reflect.NativeMethodAccessorImpl.invoke(NativeMethodAccessorImpl.java:77)
	at java.base/jdk.internal.reflect.DelegatingMethodAccessorImpl.invoke(DelegatingMethodAccessorImpl.java:43)
	at java.base/java.lang.reflect.Method.invoke(Method.java:568)
	at org.testng.internal.MethodInvocationHelper.invokeMethod(MethodInvocationHelper.java:108)
	at org.testng.internal.Invoker.invokeMethod(Invoker.java:661)
	at org.testng.internal.Invoker.retryFailed(Invoker.java:1014)
	at org.testng.internal.Invoker.invokeTestMethods(Invoker.java:1215)
	at org.testng.internal.TestMethodWorker.invokeTestMethods(TestMethodWorker.java:126)
	at org.testng.internal.TestMethodWorker.run(TestMethodWorker.java:109)
	at org.testng.TestRunner.privateRun(TestRunner.java:744)
	at org.testng.TestRunner.run(TestRunner.java:602)
	at org.testng.SuiteRunner.runTest(SuiteRunner.java:380)
	at org.testng.SuiteRunner.runSequentially(SuiteRunner.java:375)
	at org.testng.SuiteRunner.privateRun(SuiteRunner.java:340)
	at org.testng.SuiteRunner.run(SuiteRunner.java:289)
	at org.testng.SuiteRunnerWorker.runSuite(SuiteRunnerWorker.java:52)
	at org.testng.SuiteRunnerWorker.run(SuiteRunnerWorker.java:86)
	at org.testng.TestNG.runSuitesSequentially(TestNG.java:1301)
	at org.testng.TestNG.runSuitesLocally(TestNG.java:1226)
	at org.testng.TestNG.runSuites(TestNG.java:1144)
	at org.testng.TestNG.run(TestNG.java:1115)
	at org.testng.remote.AbstractRemoteTestNG.run(AbstractRemoteTestNG.java:115)
	at org.testng.remote.RemoteTestNG.initAndRun(RemoteTestNG.java:251)
	at org.testng.remote.RemoteTestNG.main(RemoteTestNG.java:77)
]]>
            </full-stacktrace>
          </exception> <!-- java.lang.AssertionError -->
          <reporter-output>
          </reporter-output>
        </test-method> <!-- noCredentials -->
        <test-method is-config="true" signature="tearDown()[pri:0, instance:com.automation.Day16_5th_May_2024_TestNG_retry_failed_TestCases.First_Way_LoginTest_retry_failed@740fb309]" started-at="2024-05-05T14:57:26Z" name="tearDown" finished-at="2024-05-05T14:57:26Z" duration-ms="275" status="PASS">
          <reporter-output>
          </reporter-output>
        </test-method> <!-- tearDown -->
      </class> <!-- com.automation.Day16_5th_May_2024_TestNG_retry_failed_TestCases.First_Way_LoginTest_retry_failed -->
    </test> <!-- Default test -->
  </suite> <!-- Default suite -->
</testng-results>
