<?xml version="1.0" encoding="UTF-8"?>
<!-- Generated by org.testng.reporters.JUnitReportReporter -->
<testsuite hostname="SarthakDell" failures="1" tests="6" name="com.automation.Day16_5th_May_2024_TestNG_retry_failed_TestCases.First_Way_LoginTest_retry_failed" time="34.173" errors="0" timestamp="05 May 2024 18:57:27 GMT" skipped="5">
  <testcase classname="com.automation.Day16_5th_May_2024_TestNG_retry_failed_TestCases.First_Way_LoginTest_retry_failed" name="noCredentials" time="5.717">
    <skipped/>
  </testcase> <!-- noCredentials -->
  <testcase classname="com.automation.Day16_5th_May_2024_TestNG_retry_failed_TestCases.First_Way_LoginTest_retry_failed" name="noCredentials" time="5.609">
    <failure message="expected [false] but found [true]" type="java.lang.AssertionError">
      <![CDATA[java.lang.AssertionError: expected [false] but found [true]
	at org.testng.Assert.fail(Assert.java:93)
	at org.testng.Assert.failNotEquals(Assert.java:512)
	at org.testng.Assert.assertFalse(Assert.java:62)
	at org.testng.Assert.assertFalse(Assert.java:72)
	at com.automation.Day16_5th_May_2024_TestNG_retry_failed_TestCases.First_Way_LoginTest_retry_failed.noCredentials(First_Way_LoginTest_retry_failed.java:72)
	at java.base/jdk.internal.reflect.NativeMethodAccessorImpl.invoke0(Native Method)
	at java.base/jdk.internal.reflect.NativeMethodAccessorImpl.invoke(NativeMethodAccessorImpl.java:77)
	at java.base/jdk.internal.reflect.DelegatingMethodAccessorImpl.invoke(DelegatingMethodAccessorImpl.java:43)
	at java.base/java.lang.reflect.Method.invoke(Method.java:568)
	at org.testng.internal.MethodInvocationHelper.invokeMethod(MethodInvocationHelper.java:108)
	at org.testng.internal.Invoker.invokeMethod(Invoker.java:661)
	at org.testng.internal.Invoker.retryFailed(Invoker.java:1014)
	at org.testng.internal.Invoker.invokeTestMethods(Invoker.java:1215)
	at org.testng.internal.TestMethodWorker.invokeTestMethods(TestMethodWorker.java:126)
	at org.testng.internal.TestMethodWorker.run(TestMethodWorker.java:109)
	at org.testng.TestRunner.privateRun(TestRunner.java:744)
	at org.testng.TestRunner.run(TestRunner.java:602)
	at org.testng.SuiteRunner.runTest(SuiteRunner.java:380)
	at org.testng.SuiteRunner.runSequentially(SuiteRunner.java:375)
	at org.testng.SuiteRunner.privateRun(SuiteRunner.java:340)
	at org.testng.SuiteRunner.run(SuiteRunner.java:289)
	at org.testng.SuiteRunnerWorker.runSuite(SuiteRunnerWorker.java:52)
	at org.testng.SuiteRunnerWorker.run(SuiteRunnerWorker.java:86)
	at org.testng.TestNG.runSuitesSequentially(TestNG.java:1301)
	at org.testng.TestNG.runSuitesLocally(TestNG.java:1226)
	at org.testng.TestNG.runSuites(TestNG.java:1144)
	at org.testng.TestNG.run(TestNG.java:1115)
	at org.testng.remote.AbstractRemoteTestNG.run(AbstractRemoteTestNG.java:115)
	at org.testng.remote.RemoteTestNG.initAndRun(RemoteTestNG.java:251)
	at org.testng.remote.RemoteTestNG.main(RemoteTestNG.java:77)
]]>
    </failure>
  </testcase> <!-- noCredentials -->
  <testcase classname="com.automation.Day16_5th_May_2024_TestNG_retry_failed_TestCases.First_Way_LoginTest_retry_failed" name="noCredentials" time="5.548">
    <skipped/>
  </testcase> <!-- noCredentials -->
  <testcase classname="com.automation.Day16_5th_May_2024_TestNG_retry_failed_TestCases.First_Way_LoginTest_retry_failed" name="noCredentials" time="6.133">
    <skipped/>
  </testcase> <!-- noCredentials -->
  <testcase classname="com.automation.Day16_5th_May_2024_TestNG_retry_failed_TestCases.First_Way_LoginTest_retry_failed" name="noCredentials" time="5.447">
    <skipped/>
  </testcase> <!-- noCredentials -->
  <testcase classname="com.automation.Day16_5th_May_2024_TestNG_retry_failed_TestCases.First_Way_LoginTest_retry_failed" name="noCredentials" time="5.719">
    <skipped/>
  </testcase> <!-- noCredentials -->
</testsuite> <!-- com.automation.Day16_5th_May_2024_TestNG_retry_failed_TestCases.First_Way_LoginTest_retry_failed -->
